[2025-03-05T04:44:24.439+0000] {local_task_job_runner.py:123} INFO - ::group::Pre task execution logs
[2025-03-05T04:44:24.508+0000] {taskinstance.py:2612} INFO - Dependencies all met for dep_context=non-requeueable deps ti=<TaskInstance: extract_stock_data.load_to_snowflake manual__2025-03-05T04:43:45.975857+00:00 [queued]>
[2025-03-05T04:44:24.534+0000] {taskinstance.py:2612} INFO - Dependencies all met for dep_context=requeueable deps ti=<TaskInstance: extract_stock_data.load_to_snowflake manual__2025-03-05T04:43:45.975857+00:00 [queued]>
[2025-03-05T04:44:24.535+0000] {taskinstance.py:2865} INFO - Starting attempt 1 of 1
[2025-03-05T04:44:24.579+0000] {taskinstance.py:2888} INFO - Executing <Task(_PythonDecoratedOperator): load_to_snowflake> on 2025-03-05 04:43:45.975857+00:00
[2025-03-05T04:44:24.646+0000] {logging_mixin.py:190} WARNING - /home/***/.local/lib/python3.12/site-packages/***/task/task_runner/standard_task_runner.py:70 DeprecationWarning: This process (pid=479) is multi-threaded, use of fork() may lead to deadlocks in the child.
[2025-03-05T04:44:24.640+0000] {standard_task_runner.py:104} INFO - Running: ['***', 'tasks', 'run', 'extract_stock_data', 'load_to_snowflake', 'manual__2025-03-05T04:43:45.975857+00:00', '--job-id', '6', '--raw', '--subdir', 'DAGS_FOLDER/extract_stock_data.py', '--cfg-path', '/tmp/tmp_mqkv7ps']
[2025-03-05T04:44:24.651+0000] {standard_task_runner.py:105} INFO - Job 6: Subtask load_to_snowflake
[2025-03-05T04:44:24.651+0000] {standard_task_runner.py:72} INFO - Started process 494 to run task
[2025-03-05T04:44:25.108+0000] {task_command.py:467} INFO - Running <TaskInstance: extract_stock_data.load_to_snowflake manual__2025-03-05T04:43:45.975857+00:00 [running]> on host 0d515916445a
[2025-03-05T04:44:25.865+0000] {taskinstance.py:3131} INFO - Exporting env vars: AIRFLOW_CTX_DAG_OWNER='***' AIRFLOW_CTX_DAG_ID='extract_stock_data' AIRFLOW_CTX_TASK_ID='load_to_snowflake' AIRFLOW_CTX_EXECUTION_DATE='2025-03-05T04:43:45.975857+00:00' AIRFLOW_CTX_TRY_NUMBER='1' AIRFLOW_CTX_DAG_RUN_ID='manual__2025-03-05T04:43:45.975857+00:00'
[2025-03-05T04:44:25.879+0000] {taskinstance.py:731} INFO - ::endgroup::
[2025-03-05T04:44:25.969+0000] {base.py:84} INFO - Retrieving connection 'snowflake_conn'
[2025-03-05T04:44:26.012+0000] {connection.py:413} INFO - Snowflake Connector for Python Version: 3.12.1, Python Version: 3.12.5, Platform: Linux-5.15.167.4-microsoft-standard-WSL2-x86_64-with-glibc2.36
[2025-03-05T04:44:26.043+0000] {connection.py:1196} INFO - Connecting to GLOBAL Snowflake domain
[2025-03-05T04:44:26.050+0000] {connection.py:1277} INFO - This connection is in OCSP Fail Open Mode. TLS Certificates would be checked for validity and revocation status. Any other Certificate Revocation related exceptions or OCSP Responder failures would be disregarded in favor of connectivity.
[2025-03-05T04:44:28.220+0000] {cursor.py:1156} INFO - Number of results in first chunk: 1
[2025-03-05T04:44:28.334+0000] {cursor.py:1156} INFO - Number of results in first chunk: 1
[2025-03-05T04:44:28.592+0000] {cursor.py:1156} INFO - Number of results in first chunk: 1
[2025-03-05T04:44:28.690+0000] {base.py:84} INFO - Retrieving connection 'snowflake_conn'
[2025-03-05T04:44:28.702+0000] {connection.py:413} INFO - Snowflake Connector for Python Version: 3.12.1, Python Version: 3.12.5, Platform: Linux-5.15.167.4-microsoft-standard-WSL2-x86_64-with-glibc2.36
[2025-03-05T04:44:28.704+0000] {connection.py:1196} INFO - Connecting to GLOBAL Snowflake domain
[2025-03-05T04:44:28.707+0000] {connection.py:1277} INFO - This connection is in OCSP Fail Open Mode. TLS Certificates would be checked for validity and revocation status. Any other Certificate Revocation related exceptions or OCSP Responder failures would be disregarded in favor of connectivity.
[2025-03-05T04:44:29.321+0000] {cursor.py:1156} INFO - Number of results in first chunk: 1
[2025-03-05T04:44:29.322+0000] {sql.py:509} INFO - Running statement: PUT 'file:///tmp/AAPL_data.csv' @dev.raw.stock_stage/AAPL_data.csv AUTO_COMPRESS=TRUE OVERWRITE=TRUE, parameters: None
[2025-03-05T04:44:30.036+0000] {file_transfer_agent.py:606} ERROR - An exception was raised in <bound method SnowflakeStorageClient.prepare_upload of <snowflake.connector.s3_storage_client.SnowflakeS3RestClient object at 0x7fd2354f1bb0>>
Traceback (most recent call last):
  File "/home/airflow/.local/lib/python3.12/site-packages/snowflake/connector/file_transfer_agent.py", line 603, in function_and_callback_wrapper
    work(*args, **kwargs),
    ^^^^^^^^^^^^^^^^^^^^^
  File "/home/airflow/.local/lib/python3.12/site-packages/snowflake/connector/storage_client.py", line 229, in prepare_upload
    self.preprocess()
  File "/home/airflow/.local/lib/python3.12/site-packages/snowflake/connector/storage_client.py", line 212, in preprocess
    self.compress()
  File "/home/airflow/.local/lib/python3.12/site-packages/snowflake/connector/storage_client.py", line 134, in compress
    ) = SnowflakeFileUtil.compress_file_with_gzip(
        ^^^^^^^^^^^^^^^^^^^^^^^^^^^^^^^^^^^^^^^^^^
  File "/home/airflow/.local/lib/python3.12/site-packages/snowflake/connector/file_util.py", line 79, in compress_file_with_gzip
    with open(file_name, "rb") as fr:
         ^^^^^^^^^^^^^^^^^^^^^
FileNotFoundError: [Errno 2] No such file or directory: '/tmp/AAPL_data.csv'
[2025-03-05T04:44:30.085+0000] {connection.py:788} INFO - closed
[2025-03-05T04:44:30.145+0000] {connection.py:794} INFO - No async queries seem to be running, deleting session
[2025-03-05T04:44:30.452+0000] {cursor.py:1156} INFO - Number of results in first chunk: 1
[2025-03-05T04:44:30.453+0000] {logging_mixin.py:190} INFO - Error loading data to Snowflake: 253003: 253003: While putting file(s) there was an error: 'FileNotFoundError(2, 'No such file or directory')', this might be caused by your access to the blob storage provider, or by Snowflake.
[2025-03-05T04:44:30.455+0000] {taskinstance.py:3310} ERROR - Task failed with exception
Traceback (most recent call last):
  File "/home/airflow/.local/lib/python3.12/site-packages/airflow/models/taskinstance.py", line 767, in _execute_task
    result = _execute_callable(context=context, **execute_callable_kwargs)
             ^^^^^^^^^^^^^^^^^^^^^^^^^^^^^^^^^^^^^^^^^^^^^^^^^^^^^^^^^^^^^
  File "/home/airflow/.local/lib/python3.12/site-packages/airflow/models/taskinstance.py", line 733, in _execute_callable
    return ExecutionCallableRunner(
           ^^^^^^^^^^^^^^^^^^^^^^^^
  File "/home/airflow/.local/lib/python3.12/site-packages/airflow/utils/operator_helpers.py", line 252, in run
    return self.func(*args, **kwargs)
           ^^^^^^^^^^^^^^^^^^^^^^^^^^
  File "/home/airflow/.local/lib/python3.12/site-packages/airflow/models/baseoperator.py", line 406, in wrapper
    return func(self, *args, **kwargs)
           ^^^^^^^^^^^^^^^^^^^^^^^^^^^
  File "/home/airflow/.local/lib/python3.12/site-packages/airflow/decorators/base.py", line 266, in execute
    return_value = super().execute(context)
                   ^^^^^^^^^^^^^^^^^^^^^^^^
  File "/home/airflow/.local/lib/python3.12/site-packages/airflow/models/baseoperator.py", line 406, in wrapper
    return func(self, *args, **kwargs)
           ^^^^^^^^^^^^^^^^^^^^^^^^^^^
  File "/home/airflow/.local/lib/python3.12/site-packages/airflow/operators/python.py", line 238, in execute
    return_value = self.execute_callable()
                   ^^^^^^^^^^^^^^^^^^^^^^^
  File "/home/airflow/.local/lib/python3.12/site-packages/airflow/operators/python.py", line 256, in execute_callable
    return runner.run(*self.op_args, **self.op_kwargs)
           ^^^^^^^^^^^^^^^^^^^^^^^^^^^^^^^^^^^^^^^^^^^
  File "/home/airflow/.local/lib/python3.12/site-packages/airflow/utils/operator_helpers.py", line 252, in run
    return self.func(*args, **kwargs)
           ^^^^^^^^^^^^^^^^^^^^^^^^^^
  File "/opt/airflow/dags/extract_stock_data.py", line 72, in load_to_snowflake
    hook.run(f"PUT 'file://{file_path}' @{SNOWFLAKE_STAGE}/{file_name} AUTO_COMPRESS=TRUE OVERWRITE=TRUE")
  File "/home/airflow/.local/lib/python3.12/site-packages/airflow/providers/snowflake/hooks/snowflake.py", line 410, in run
    self._run_command(cur, sql_statement, parameters)  # type: ignore[attr-defined]
    ^^^^^^^^^^^^^^^^^^^^^^^^^^^^^^^^^^^^^^^^^^^^^^^^^
  File "/home/airflow/.local/lib/python3.12/site-packages/airflow/providers/common/sql/hooks/sql.py", line 514, in _run_command
    cur.execute(sql_statement)
  File "/home/airflow/.local/lib/python3.12/site-packages/snowflake/connector/cursor.py", line 1054, in execute
    data = sf_file_transfer_agent.result()
           ^^^^^^^^^^^^^^^^^^^^^^^^^^^^^^^
  File "/home/airflow/.local/lib/python3.12/site-packages/snowflake/connector/file_transfer_agent.py", line 740, in result
    Error.errorhandler_wrapper(
  File "/home/airflow/.local/lib/python3.12/site-packages/snowflake/connector/errors.py", line 284, in errorhandler_wrapper
    handed_over = Error.hand_to_other_handler(
                  ^^^^^^^^^^^^^^^^^^^^^^^^^^^^
  File "/home/airflow/.local/lib/python3.12/site-packages/snowflake/connector/errors.py", line 339, in hand_to_other_handler
    cursor.errorhandler(connection, cursor, error_class, error_value)
  File "/home/airflow/.local/lib/python3.12/site-packages/snowflake/connector/errors.py", line 215, in default_errorhandler
    raise error_class(
snowflake.connector.errors.OperationalError: 253003: 253003: While putting file(s) there was an error: 'FileNotFoundError(2, 'No such file or directory')', this might be caused by your access to the blob storage provider, or by Snowflake.
[2025-03-05T04:44:30.487+0000] {taskinstance.py:1225} INFO - Marking task as FAILED. dag_id=extract_stock_data, task_id=load_to_snowflake, run_id=manual__2025-03-05T04:43:45.975857+00:00, execution_date=20250305T044345, start_date=20250305T044424, end_date=20250305T044430
[2025-03-05T04:44:30.509+0000] {taskinstance.py:340} INFO - ::group::Post task execution logs
[2025-03-05T04:44:30.531+0000] {standard_task_runner.py:124} ERROR - Failed to execute job 6 for task load_to_snowflake (253003: 253003: While putting file(s) there was an error: 'FileNotFoundError(2, 'No such file or directory')', this might be caused by your access to the blob storage provider, or by Snowflake.; 494)
Traceback (most recent call last):
  File "/home/airflow/.local/lib/python3.12/site-packages/airflow/task/task_runner/standard_task_runner.py", line 117, in _start_by_fork
    ret = args.func(args, dag=self.dag)
          ^^^^^^^^^^^^^^^^^^^^^^^^^^^^^
  File "/home/airflow/.local/lib/python3.12/site-packages/airflow/cli/cli_config.py", line 49, in command
    return func(*args, **kwargs)
           ^^^^^^^^^^^^^^^^^^^^^
  File "/home/airflow/.local/lib/python3.12/site-packages/airflow/utils/cli.py", line 115, in wrapper
    return f(*args, **kwargs)
           ^^^^^^^^^^^^^^^^^^
  File "/home/airflow/.local/lib/python3.12/site-packages/airflow/cli/commands/task_command.py", line 483, in task_run
    task_return_code = _run_task_by_selected_method(args, _dag, ti)
                       ^^^^^^^^^^^^^^^^^^^^^^^^^^^^^^^^^^^^^^^^^^^^
  File "/home/airflow/.local/lib/python3.12/site-packages/airflow/cli/commands/task_command.py", line 256, in _run_task_by_selected_method
    return _run_raw_task(args, ti)
           ^^^^^^^^^^^^^^^^^^^^^^^
  File "/home/airflow/.local/lib/python3.12/site-packages/airflow/cli/commands/task_command.py", line 341, in _run_raw_task
    return ti._run_raw_task(
           ^^^^^^^^^^^^^^^^^
  File "/home/airflow/.local/lib/python3.12/site-packages/airflow/utils/session.py", line 97, in wrapper
    return func(*args, session=session, **kwargs)
           ^^^^^^^^^^^^^^^^^^^^^^^^^^^^^^^^^^^^^^
  File "/home/airflow/.local/lib/python3.12/site-packages/airflow/models/taskinstance.py", line 3004, in _run_raw_task
    return _run_raw_task(
           ^^^^^^^^^^^^^^
  File "/home/airflow/.local/lib/python3.12/site-packages/airflow/models/taskinstance.py", line 273, in _run_raw_task
    TaskInstance._execute_task_with_callbacks(
  File "/home/airflow/.local/lib/python3.12/site-packages/airflow/models/taskinstance.py", line 3158, in _execute_task_with_callbacks
    result = self._execute_task(context, task_orig)
             ^^^^^^^^^^^^^^^^^^^^^^^^^^^^^^^^^^^^^^
  File "/home/airflow/.local/lib/python3.12/site-packages/airflow/models/taskinstance.py", line 3182, in _execute_task
    return _execute_task(self, context, task_orig)
           ^^^^^^^^^^^^^^^^^^^^^^^^^^^^^^^^^^^^^^^
  File "/home/airflow/.local/lib/python3.12/site-packages/airflow/models/taskinstance.py", line 767, in _execute_task
    result = _execute_callable(context=context, **execute_callable_kwargs)
             ^^^^^^^^^^^^^^^^^^^^^^^^^^^^^^^^^^^^^^^^^^^^^^^^^^^^^^^^^^^^^
  File "/home/airflow/.local/lib/python3.12/site-packages/airflow/models/taskinstance.py", line 733, in _execute_callable
    return ExecutionCallableRunner(
           ^^^^^^^^^^^^^^^^^^^^^^^^
  File "/home/airflow/.local/lib/python3.12/site-packages/airflow/utils/operator_helpers.py", line 252, in run
    return self.func(*args, **kwargs)
           ^^^^^^^^^^^^^^^^^^^^^^^^^^
  File "/home/airflow/.local/lib/python3.12/site-packages/airflow/models/baseoperator.py", line 406, in wrapper
    return func(self, *args, **kwargs)
           ^^^^^^^^^^^^^^^^^^^^^^^^^^^
  File "/home/airflow/.local/lib/python3.12/site-packages/airflow/decorators/base.py", line 266, in execute
    return_value = super().execute(context)
                   ^^^^^^^^^^^^^^^^^^^^^^^^
  File "/home/airflow/.local/lib/python3.12/site-packages/airflow/models/baseoperator.py", line 406, in wrapper
    return func(self, *args, **kwargs)
           ^^^^^^^^^^^^^^^^^^^^^^^^^^^
  File "/home/airflow/.local/lib/python3.12/site-packages/airflow/operators/python.py", line 238, in execute
    return_value = self.execute_callable()
                   ^^^^^^^^^^^^^^^^^^^^^^^
  File "/home/airflow/.local/lib/python3.12/site-packages/airflow/operators/python.py", line 256, in execute_callable
    return runner.run(*self.op_args, **self.op_kwargs)
           ^^^^^^^^^^^^^^^^^^^^^^^^^^^^^^^^^^^^^^^^^^^
  File "/home/airflow/.local/lib/python3.12/site-packages/airflow/utils/operator_helpers.py", line 252, in run
    return self.func(*args, **kwargs)
           ^^^^^^^^^^^^^^^^^^^^^^^^^^
  File "/opt/airflow/dags/extract_stock_data.py", line 72, in load_to_snowflake
    hook.run(f"PUT 'file://{file_path}' @{SNOWFLAKE_STAGE}/{file_name} AUTO_COMPRESS=TRUE OVERWRITE=TRUE")
  File "/home/airflow/.local/lib/python3.12/site-packages/airflow/providers/snowflake/hooks/snowflake.py", line 410, in run
    self._run_command(cur, sql_statement, parameters)  # type: ignore[attr-defined]
    ^^^^^^^^^^^^^^^^^^^^^^^^^^^^^^^^^^^^^^^^^^^^^^^^^
  File "/home/airflow/.local/lib/python3.12/site-packages/airflow/providers/common/sql/hooks/sql.py", line 514, in _run_command
    cur.execute(sql_statement)
  File "/home/airflow/.local/lib/python3.12/site-packages/snowflake/connector/cursor.py", line 1054, in execute
    data = sf_file_transfer_agent.result()
           ^^^^^^^^^^^^^^^^^^^^^^^^^^^^^^^
  File "/home/airflow/.local/lib/python3.12/site-packages/snowflake/connector/file_transfer_agent.py", line 740, in result
    Error.errorhandler_wrapper(
  File "/home/airflow/.local/lib/python3.12/site-packages/snowflake/connector/errors.py", line 284, in errorhandler_wrapper
    handed_over = Error.hand_to_other_handler(
                  ^^^^^^^^^^^^^^^^^^^^^^^^^^^^
  File "/home/airflow/.local/lib/python3.12/site-packages/snowflake/connector/errors.py", line 339, in hand_to_other_handler
    cursor.errorhandler(connection, cursor, error_class, error_value)
  File "/home/airflow/.local/lib/python3.12/site-packages/snowflake/connector/errors.py", line 215, in default_errorhandler
    raise error_class(
snowflake.connector.errors.OperationalError: 253003: 253003: While putting file(s) there was an error: 'FileNotFoundError(2, 'No such file or directory')', this might be caused by your access to the blob storage provider, or by Snowflake.
[2025-03-05T04:44:30.634+0000] {local_task_job_runner.py:266} INFO - Task exited with return code 1
[2025-03-05T04:44:30.663+0000] {local_task_job_runner.py:245} INFO - ::endgroup::
